<?xml version="1.0" ?>
<!-- =================================================================================== -->
<!-- |    This document was autogenerated by xacro from j2n6a300_standalone.xacro      | -->
<!-- |    EDITING THIS FILE BY HAND IS NOT RECOMMENDED                                 | -->
<!-- =================================================================================== -->
<!-- j2n6a300 refers to jaco v2 6DOF non-spherical 3fingers -->
<robot name="JACO" xmlns:body="http://playerstage.sourceforge.net/gazebo/xmlschema/#body" xmlns:controller="http://playerstage.sourceforge.net/gazebo/xmlschema/#controller" xmlns:gazebo="http://playerstage.sourceforge.net/gazebo/xmlschema/#gz" xmlns:geom="http://playerstage.sourceforge.net/gazebo/xmlschema/#geom" xmlns:interface="http://playerstage.sourceforge.net/gazebo/xmlschema/#interface" xmlns:joint="http://playerstage.sourceforge.net/gazebo/xmlschema/#joint" xmlns:model="http://playerstage.sourceforge.net/gazebo/xmlschema/#model" xmlns:physics="http://playerstage.sourceforge.net/gazebo/xmlschema/#physics" xmlns:renderable="http://playerstage.sourceforge.net/gazebo/xmlschema/#renderable" xmlns:rendering="http://playerstage.sourceforge.net/gazebo/xmlschema/#rendering" xmlns:sensor="http://playerstage.sourceforge.net/gazebo/xmlschema/#sensor" xmlns:xacro="http://ros.org/wiki/xacro" xmlns:xi="http://www.w3.org/2001/XInclude">
  <!-- finger1 Rot := Ry((1/2)*Pi) . Rx(12.1*((1/180)*Pi)+Pi) . Rz(-52.8*((1/180)*Pi)) -->
  <link name="j2n6a300_link_finger_1">
    <visual>
      <geometry>
        <mesh filename="package://ada_description/meshes/finger_proximal.dae"/>
      </geometry>
      <material name="carbon_fiber">
        <color rgba="0.792156862745098 0.819607843137255 0.933333333333333 1"/>
      </material>
    </visual>
    <collision>
      <geometry>
        <mesh filename="package://ada_description/meshes/finger_proximal.dae"/>
      </geometry>
    </collision>
  </link>
  <joint name="j2n6a300_joint_finger_1" type="revolute">
    <parent link="j2n6a300_link_6"/>
    <child link="j2n6a300_link_finger_1"/>
    <axis xyz="0 0 1"/>
    <origin rpy="-1.570796327 .649262481663582 1.35961148639407" xyz="0.00279 0.03126 -0.11467"/>
    <limit effort="30" lower="0" upper="2" velocity="5"/>
  </joint>
  <link name="j2n6a300_link_finger_tip_1">
    <visual>
      <geometry>
        <mesh filename="package://ada_description/meshes/finger_distal.dae"/>
      </geometry>
      <material name="carbon_fiber">
        <color rgba="0.792156862745098 0.819607843137255 0.933333333333333 1"/>
      </material>
    </visual>
    <collision>
      <geometry>
        <mesh filename="package://ada_description/meshes/finger_distal.dae"/>
      </geometry>
    </collision>
  </link>
  <joint name="j2n6a300_joint_finger_tip_1" type="fixed">
    <parent link="j2n6a300_link_finger_1"/>
    <child link="j2n6a300_link_finger_tip_1"/>
    <axis xyz="0 0 1"/>
    <origin rpy="0 0 0" xyz="0.044 -0.003 0"/>
    <limit effort="30" lower="0" upper="2" velocity="5"/>
    <mimic joint="0.698131700798" multiplier="1.0" offset="0.0"/>
  </joint>
  <!-- finger2 Rot := Ry((1/2)*Pi) . Rx(10.58*((1/180)*Pi)) . Rz(-52.8*((1/180)*Pi)) -->
  <link name="j2n6a300_link_finger_2">
    <visual>
      <geometry>
        <mesh filename="package://ada_description/meshes/finger_proximal.dae"/>
      </geometry>
      <material name="carbon_fiber">
        <color rgba="0.792156862745098 0.819607843137255 0.933333333333333 1"/>
      </material>
    </visual>
    <collision>
      <geometry>
        <mesh filename="package://ada_description/meshes/finger_proximal.dae"/>
      </geometry>
    </collision>
  </link>
  <joint name="j2n6a300_joint_finger_2" type="revolute">
    <parent link="j2n6a300_link_6"/>
    <child link="j2n6a300_link_finger_2"/>
    <axis xyz="0 0 1"/>
    <origin rpy="-1.570796327 .649262481663582 -1.75545216211587" xyz="-0.02226 -0.02707 -0.11482"/>
    <limit effort="30" lower="0" upper="2" velocity="5"/>
  </joint>
  <link name="j2n6a300_link_finger_tip_2">
    <visual>
      <geometry>
        <mesh filename="package://ada_description/meshes/finger_distal.dae"/>
      </geometry>
      <material name="carbon_fiber">
        <color rgba="0.792156862745098 0.819607843137255 0.933333333333333 1"/>
      </material>
    </visual>
    <collision>
      <geometry>
        <mesh filename="package://ada_description/meshes/finger_distal.dae"/>
      </geometry>
    </collision>
  </link>
  <joint name="j2n6a300_joint_finger_tip_2" type="fixed">
    <parent link="j2n6a300_link_finger_2"/>
    <child link="j2n6a300_link_finger_tip_2"/>
    <axis xyz="0 0 1"/>
    <origin rpy="0 0 0" xyz="0.044 -0.003 0"/>
    <limit effort="30" lower="0" upper="2" velocity="5"/>
    <mimic joint="0.698131700798" multiplier="1.0" offset="0.0"/>
  </joint>
  <!-- finger3 Rot := Ry((1/2)*Pi) . Rx(-10.58*((1/180)*Pi)) . Rz(-52.8*((1/180)*Pi)) -->
  <link name="j2n6a300_link_finger_3">
    <visual>
      <geometry>
        <mesh filename="package://ada_description/meshes/finger_proximal.dae"/>
      </geometry>
      <material name="carbon_fiber">
        <color rgba="0.792156862745098 0.819607843137255 0.933333333333333 1"/>
      </material>
    </visual>
    <collision>
      <geometry>
        <mesh filename="package://ada_description/meshes/finger_proximal.dae"/>
      </geometry>
    </collision>
  </link>
  <joint name="j2n6a300_joint_finger_3" type="revolute">
    <parent link="j2n6a300_link_6"/>
    <child link="j2n6a300_link_finger_3"/>
    <axis xyz="0 0 1"/>
    <origin rpy="-1.570796327 .649262481663582 -1.38614049188413" xyz="0.02226 -0.02707 -0.11482"/>
    <limit effort="30" lower="0" upper="2" velocity="5"/>
  </joint>
  <link name="j2n6a300_link_finger_tip_3">
    <visual>
      <geometry>
        <mesh filename="package://ada_description/meshes/finger_distal.dae"/>
      </geometry>
      <material name="carbon_fiber">
        <color rgba="0.792156862745098 0.819607843137255 0.933333333333333 1"/>
      </material>
    </visual>
    <collision>
      <geometry>
        <mesh filename="package://ada_description/meshes/finger_distal.dae"/>
      </geometry>
    </collision>
  </link>
  <joint name="j2n6a300_joint_finger_tip_3" type="fixed">
    <parent link="j2n6a300_link_finger_3"/>
    <child link="j2n6a300_link_finger_tip_3"/>
    <axis xyz="0 0 1"/>
    <origin rpy="0 0 0" xyz="0.044 -0.003 0"/>
    <limit effort="30" lower="0" upper="2" velocity="5"/>
    <mimic joint="0.698131700798" multiplier="1.0" offset="0.0"/>
  </joint>
  <link name="root">
    <visual>
      <origin rpy="0 0 0" xyz="0 0 0"/>
      <geometry>
        <box size="0 0 0"/>
      </geometry>
      <!--<material name="Black" /> -->
    </visual>
    <collision>
      <origin rpy="0 0 0" xyz="0 0 0"/>
      <geometry>
        <box size="0 0 0"/>
      </geometry>
    </collision>
  </link>
  <link name="j2n6a300_link_base">
    <visual>
      <geometry>
        <mesh filename="package://ada_description/meshes/base.dae"/>
      </geometry>
      <material name="carbon_fiber">
        <color rgba="0.792156862745098 0.819607843137255 0.933333333333333 1"/>
      </material>
    </visual>
    <collision>
      <geometry>
        <mesh filename="package://ada_description/meshes/base.dae"/>
      </geometry>
    </collision>
  </link>
  <joint name="j2n6a300_joint_base" type="fixed">
    <parent link="root"/>
    <child link="j2n6a300_link_base"/>
    <axis xyz="0 0 0"/>
    <limit effort="30" lower="0" upper="0" velocity="0.35"/>
    <origin rpy="0 0 0" xyz="0 0 0"/>
  </joint>
  <link name="j2n6a300_link_1">
    <visual>
      <geometry>
        <mesh filename="package://ada_description/meshes/shoulder.dae"/>
      </geometry>
      <material name="carbon_fiber">
        <color rgba="0.792156862745098 0.819607843137255 0.933333333333333 1"/>
      </material>
    </visual>
    <collision>
      <geometry>
        <mesh filename="package://ada_description/meshes/shoulder.dae"/>
      </geometry>
    </collision>
  </link>
  <joint name="j2n6a300_joint_1" type="continuous">
    <parent link="j2n6a300_link_base"/>
    <child link="j2n6a300_link_1"/>
    <axis xyz="0 0 1"/>
    <limit effort="30" lower="-6.28318530718" upper="6.28318530718" velocity="0.35"/>
    <origin rpy="0 3.14159265359 0" xyz="0 0 0.15675"/>
  </joint>
  <link name="j2n6a300_link_2">
    <visual>
      <geometry>
        <mesh filename="package://ada_description/meshes/arm.dae"/>
      </geometry>
      <material name="carbon_fiber">
        <color rgba="0.792156862745098 0.819607843137255 0.933333333333333 1"/>
      </material>
    </visual>
    <collision>
      <geometry>
        <mesh filename="package://ada_description/meshes/arm.dae"/>
      </geometry>
    </collision>
  </link>
  <joint name="j2n6a300_joint_2" type="continuous">
    <parent link="j2n6a300_link_1"/>
    <child link="j2n6a300_link_2"/>
    <axis xyz="0 0 1"/>
    <limit effort="30" lower="-2.35" upper="2.35" velocity="0.35"/>
    <origin rpy="-1.57079632679 0 3.14159265359" xyz="0 0.0016 -0.11875"/>
  </joint>
  <link name="j2n6a300_link_3">
    <visual>
      <geometry>
        <mesh filename="package://ada_description/meshes/forearm.dae"/>
      </geometry>
      <material name="carbon_fiber">
        <color rgba="0.792156862745098 0.819607843137255 0.933333333333333 1"/>
      </material>
    </visual>
    <collision>
      <geometry>
        <mesh filename="package://ada_description/meshes/forearm.dae"/>
      </geometry>
    </collision>
  </link>
  <joint name="j2n6a300_joint_3" type="continuous">
    <parent link="j2n6a300_link_2"/>
    <child link="j2n6a300_link_3"/>
    <axis xyz="0 0 1"/>
    <limit effort="30" lower="-2.65" upper="2.65" velocity="0.35"/>
    <origin rpy="0 3.14159265359 0" xyz="0 -0.410 0"/>
  </joint>
  <link name="j2n6a300_link_4">
    <visual>
      <geometry>
        <mesh filename="package://ada_description/meshes/wrist.dae"/>
      </geometry>
      <material name="carbon_fiber">
        <color rgba="0.792156862745098 0.819607843137255 0.933333333333333 1"/>
      </material>
    </visual>
    <collision>
      <geometry>
        <mesh filename="package://ada_description/meshes/wrist.dae"/>
      </geometry>
    </collision>
  </link>
  <joint name="j2n6a300_joint_4" type="continuous">
    <parent link="j2n6a300_link_3"/>
    <child link="j2n6a300_link_4"/>
    <axis xyz="0 0 1"/>
    <limit effort="30" lower="-6.28318530718" upper="6.28318530718" velocity="0.35"/>
    <origin rpy="-1.57079632679 0 3.14159265359" xyz="0 0.2073 -0.0114"/>
  </joint>
  <link name="j2n6a300_link_5">
    <visual>
      <geometry>
        <mesh filename="package://ada_description/meshes/wrist.dae"/>
      </geometry>
      <material name="carbon_fiber">
        <color rgba="0.792156862745098 0.819607843137255 0.933333333333333 1"/>
      </material>
    </visual>
    <collision>
      <geometry>
        <mesh filename="package://ada_description/meshes/wrist.dae"/>
      </geometry>
    </collision>
  </link>
  <joint name="j2n6a300_joint_5" type="continuous">
    <parent link="j2n6a300_link_4"/>
    <child link="j2n6a300_link_5"/>
    <axis xyz="0 0 1"/>
    <limit effort="30" lower="-6.28318530718" upper="6.28318530718" velocity="0.35"/>
    <origin rpy="1.0471975512 0 3.14159265359" xyz="0 -0.03703 -0.06414"/>
  </joint>
  <link name="j2n6a300_link_6">
    <visual>
      <geometry>
        <mesh filename="package://ada_description/meshes/hand_3finger.dae"/>
      </geometry>
      <material name="carbon_fiber">
        <color rgba="0.792156862745098 0.819607843137255 0.933333333333333 1"/>
      </material>
    </visual>
    <collision>
      <geometry>
        <mesh filename="package://ada_description/meshes/hand_3finger.dae"/>
      </geometry>
    </collision>
  </link>
  <joint name="j2n6a300_joint_6" type="continuous">
    <parent link="j2n6a300_link_5"/>
    <child link="j2n6a300_link_6"/>
    <axis xyz="0 0 1"/>
    <limit effort="30" lower="-6.28318530718" upper="6.28318530718" velocity="0.35"/>
    <origin rpy="1.0471975512 0 3.14159265359" xyz="0 -0.03703 -0.06414"/>
  </joint>
  <link name="j2n6a300_end_effector">
    <visual>
      <geometry>
        <box size="0 0 0"/>
      </geometry>
    </visual>
    <collision>
      <geometry>
        <box size="0 0 0"/>
      </geometry>
    </collision>
  </link>

  <link
    name="Camera_Depth_Frame">
    <inertial>
      <origin
        xyz="0 0 0"
        rpy="0 0 0" />
      <mass
        value="0.05" />
      <inertia
        ixx="0"
        ixy="0"
        ixz="0"
        iyy="0"
        iyz="0"
        izz="0" />
    </inertial>
  </link>
   <joint
    name="Camera_Joint" type = "fixed">
    <origin
      xyz="-0.047 0.05 -0.090 "
      rpy="-2.92 0.000 0" />
    <parent
      link="j2n6a300_link_6" />
    <child
      link="Camera_Depth_Frame" />
  </joint>
  <joint
    name="Camera_Depth_Joint" type = "fixed">
    <origin
      xyz="0.045 -0.015 -0.03"
      rpy="0 0.000 0" />
    <parent
      link="Camera_Depth_Frame" />
    <child
      link="Camera_RGB_Frame" />
  </joint>
   <link
    name="Camera_RGB_Frame">
        <inertial>
      <origin
        xyz="0 0 0"
        rpy="0 0 0" />
      <mass
        value="0.05" />
      <inertia
        ixx="0"
        ixy="0"
        ixz="0"
        iyy="0"
        iyz="0"
        izz="0" />
    </inertial>
  </link>


  <joint name="j2n6a300_end_effector_offset" type="fixed">
    <parent link="j2n6a300_link_6"/>
    <child link="j2n6a300_end_effector"/>
    <axis xyz="0 0 0"/>
    <limit effort="30" lower="0" upper="0" velocity="0.35"/>
    <origin rpy="3.14159265359 0 0" xyz="0 0 -0.1600"/>
  </joint>
</robot>
<!--
  <joint name="j2n6a300_end_effector_offset" type="fixed">
    <parent link="j2n6a300_link_6"/>
    <child link="j2n6a300_end_effector"/>
    <axis xyz="0 0 0"/>
    <limit effort="30" lower="0" upper="0" velocity="0.35"/>
    <origin rpy="0 0 1.570795" xyz="0 0 0.000"/>
  </joint>
-->
</robot>
